<?xml version='1.0' encoding='UTF-8'?>
<robot name="robot">
  <link name="0">
    <inertial>
      <origin xyz="0.0 0.0 0.0" rpy="0.0 0.0 0.0"/>
      <mass value="0.6162799829535238"/>
      <inertia ixx="0.0023255075838833346" ixy="2.0175850590575663e-20" ixz="3.15683461770036e-05" iyy="0.004910519848350381" iyz="1.3284306943909567e-20" izz="0.006275332679553604"/>
    </inertial>
    <visual>
      <origin xyz="0.0 0.0 0.0" rpy="0.0 0.0 0.0"/>
      <geometry>
        <mesh filename="mesh/0.obj"/>
      </geometry>
      <material name="#ff0000ff">
        <color rgba="1.0 0.0 0.0 1"/>
      </material>
    </visual>
    <collision>
      <origin xyz="0.0 0.0 0.0" rpy="0.0 0.0 0.0"/>
      <geometry>
        <mesh filename="mesh/0.obj"/>
      </geometry>
    </collision>
  </link>
  <link name="1">
    <inertial>
      <origin xyz="0.0 0.0 0.0" rpy="0.0 0.0 0.0"/>
      <mass value="0.07269017067211427"/>
      <inertia ixx="5.890215759579382e-05" ixy="3.019754432705555e-10" ixz="5.436432049982791e-11" iyy="8.024576882477195e-05" iyz="-6.214062745464443e-11" izz="6.418317475691778e-05"/>
    </inertial>
    <visual>
      <origin xyz="0.0 0.0 0.0" rpy="0.0 0.0 0.0"/>
      <geometry>
        <mesh filename="mesh/1.obj"/>
      </geometry>
      <material name="#008000ff">
        <color rgba="0.0 0.5 0.0 1"/>
      </material>
    </visual>
    <collision>
      <origin xyz="0.0 0.0 0.0" rpy="0.0 0.0 0.0"/>
      <geometry>
        <mesh filename="mesh/1.obj"/>
      </geometry>
    </collision>
  </link>
  <link name="2">
    <inertial>
      <origin xyz="0.0 0.0 0.0" rpy="0.0 0.0 0.0"/>
      <mass value="0.09857950140569696"/>
      <inertia ixx="0.00015801174289584922" ixy="3.105787473265769e-22" ixz="5.310444628340301e-22" iyy="0.00017389559096697184" iyz="1.2148912375055951e-20" izz="7.613674281767581e-05"/>
    </inertial>
    <visual>
      <origin xyz="0.0 0.0 0.0" rpy="0.0 0.0 0.0"/>
      <geometry>
        <mesh filename="mesh/2.obj"/>
      </geometry>
      <material name="#ffffffff">
        <color rgba="1 1 1 1"/>
      </material>
    </visual>
    <collision>
      <origin xyz="0.0 0.0 0.0" rpy="0.0 0.0 0.0"/>
      <geometry>
        <mesh filename="mesh/2.obj"/>
      </geometry>
    </collision>
  </link>
  <link name="3">
    <inertial>
      <origin xyz="0.0 0.0 0.0" rpy="0.0 0.0 0.0"/>
      <mass value="0.05961127877722497"/>
      <inertia ixx="6.143768285533723e-05" ixy="2.6245108516620497e-10" ixz="-9.28399731434094e-11" iyy="6.001893411295294e-05" iyz="-5.141603680911952e-10" izz="3.627869762810086e-05"/>
    </inertial>
    <visual>
      <origin xyz="0.0 0.0 0.0" rpy="0.0 0.0 0.0"/>
      <geometry>
        <mesh filename="mesh/3.obj"/>
      </geometry>
      <material name="#0000ffff">
        <color rgba="0.0 0.0 1.0 1"/>
      </material>
    </visual>
    <collision>
      <origin xyz="0.0 0.0 0.0" rpy="0.0 0.0 0.0"/>
      <geometry>
        <mesh filename="mesh/3.obj"/>
      </geometry>
    </collision>
  </link>
  <link name="4">
    <inertial>
      <origin xyz="0.0 0.0 0.0" rpy="0.0 0.0 0.0"/>
      <mass value="0.07269017067211427"/>
      <inertia ixx="5.890215759579382e-05" ixy="3.019754432705555e-10" ixz="5.436432049982791e-11" iyy="8.024576882477195e-05" iyz="-6.214062745464443e-11" izz="6.418317475691778e-05"/>
    </inertial>
    <visual>
      <origin xyz="0.0 0.0 0.0" rpy="0.0 0.0 0.0"/>
      <geometry>
        <mesh filename="mesh/4.obj"/>
      </geometry>
      <material name="#008000ff">
        <color rgba="0.0 0.5 0.0 1"/>
      </material>
    </visual>
    <collision>
      <origin xyz="0.0 0.0 0.0" rpy="0.0 0.0 0.0"/>
      <geometry>
        <mesh filename="mesh/4.obj"/>
      </geometry>
    </collision>
  </link>
  <link name="5">
    <inertial>
      <origin xyz="0.0 0.0 0.0" rpy="0.0 0.0 0.0"/>
      <mass value="0.09857950140569696"/>
      <inertia ixx="0.00015801174289584922" ixy="3.105787473265769e-22" ixz="5.310444628340301e-22" iyy="0.00017389559096697184" iyz="1.2148912375055951e-20" izz="7.613674281767581e-05"/>
    </inertial>
    <visual>
      <origin xyz="0.0 0.0 0.0" rpy="0.0 0.0 0.0"/>
      <geometry>
        <mesh filename="mesh/5.obj"/>
      </geometry>
      <material name="#ffffffff">
        <color rgba="1 1 1 1"/>
      </material>
    </visual>
    <collision>
      <origin xyz="0.0 0.0 0.0" rpy="0.0 0.0 0.0"/>
      <geometry>
        <mesh filename="mesh/5.obj"/>
      </geometry>
    </collision>
  </link>
  <link name="6">
    <inertial>
      <origin xyz="0.0 0.0 0.0" rpy="0.0 0.0 0.0"/>
      <mass value="0.05961127877722497"/>
      <inertia ixx="6.143768285533723e-05" ixy="2.6245108516620497e-10" ixz="-9.28399731434094e-11" iyy="6.001893411295294e-05" iyz="-5.141603680911952e-10" izz="3.627869762810086e-05"/>
    </inertial>
    <visual>
      <origin xyz="0.0 0.0 0.0" rpy="0.0 0.0 0.0"/>
      <geometry>
        <mesh filename="mesh/6.obj"/>
      </geometry>
      <material name="#0000ffff">
        <color rgba="0.0 0.0 1.0 1"/>
      </material>
    </visual>
    <collision>
      <origin xyz="0.0 0.0 0.0" rpy="0.0 0.0 0.0"/>
      <geometry>
        <mesh filename="mesh/6.obj"/>
      </geometry>
    </collision>
  </link>
  <link name="7">
    <inertial>
      <origin xyz="0.0 0.0 0.0" rpy="0.0 0.0 0.0"/>
      <mass value="0.1338270472340628"/>
      <inertia ixx="0.0003791910546099741" ixy="7.61820550434531e-21" ixz="-0.0" iyy="0.00035722003966505726" iyz="-5.731672263749545e-21" izz="0.00010226724328535455"/>
    </inertial>
    <visual>
      <origin xyz="0.0 0.0 0.0" rpy="0.0 0.0 0.0"/>
      <geometry>
        <mesh filename="mesh/7.obj"/>
      </geometry>
      <material name="#008000ff">
        <color rgba="0.0 0.5 0.0 1"/>
      </material>
    </visual>
    <collision>
      <origin xyz="0.0 0.0 0.0" rpy="0.0 0.0 0.0"/>
      <geometry>
        <mesh filename="mesh/7.obj"/>
      </geometry>
    </collision>
  </link>
  <link name="8">
    <inertial>
      <origin xyz="0.0 0.0 0.0" rpy="0.0 0.0 0.0"/>
      <mass value="0.0921671006538613"/>
      <inertia ixx="0.00014039564834146355" ixy="-5.358429276238181e-38" ixz="6.6835965943204566e-21" iyy="0.00011959285834791852" iyz="-9.863951991018341e-21" izz="7.610305038586184e-05"/>
    </inertial>
    <visual>
      <origin xyz="0.0 0.0 0.0" rpy="0.0 0.0 0.0"/>
      <geometry>
        <mesh filename="mesh/8.obj"/>
      </geometry>
      <material name="#ffffffff">
        <color rgba="1 1 1 1"/>
      </material>
    </visual>
    <collision>
      <origin xyz="0.0 0.0 0.0" rpy="0.0 0.0 0.0"/>
      <geometry>
        <mesh filename="mesh/8.obj"/>
      </geometry>
    </collision>
  </link>
  <link name="9">
    <inertial>
      <origin xyz="0.0 0.0 0.0" rpy="0.0 0.0 0.0"/>
      <mass value="0.053982565927089526"/>
      <inertia ixx="6.022603028687575e-05" ixy="3.8406801277886185e-22" ixz="5.856544563432322e-21" iyy="2.9535889368881557e-05" iyz="-3.058626151082641e-06" izz="6.307968047424788e-05"/>
    </inertial>
    <visual>
      <origin xyz="0.0 0.0 0.0" rpy="0.0 0.0 0.0"/>
      <geometry>
        <mesh filename="mesh/9.obj"/>
      </geometry>
      <material name="#0000ffff">
        <color rgba="0.0 0.0 1.0 1"/>
      </material>
    </visual>
    <collision>
      <origin xyz="0.0 0.0 0.0" rpy="0.0 0.0 0.0"/>
      <geometry>
        <mesh filename="mesh/9.obj"/>
      </geometry>
    </collision>
  </link>
  <link name="10">
    <inertial>
      <origin xyz="0.0 0.0 0.0" rpy="0.0 0.0 0.0"/>
      <mass value="0.1338270472340628"/>
      <inertia ixx="0.0003791910546099741" ixy="7.61820550434531e-21" ixz="-0.0" iyy="0.00035722003966505726" iyz="-5.731672263749545e-21" izz="0.00010226724328535455"/>
    </inertial>
    <visual>
      <origin xyz="0.0 0.0 0.0" rpy="0.0 0.0 0.0"/>
      <geometry>
        <mesh filename="mesh/10.obj"/>
      </geometry>
      <material name="#008000ff">
        <color rgba="0.0 0.5 0.0 1"/>
      </material>
    </visual>
    <collision>
      <origin xyz="0.0 0.0 0.0" rpy="0.0 0.0 0.0"/>
      <geometry>
        <mesh filename="mesh/10.obj"/>
      </geometry>
    </collision>
  </link>
  <link name="11">
    <inertial>
      <origin xyz="0.0 0.0 0.0" rpy="0.0 0.0 0.0"/>
      <mass value="0.0921671006538613"/>
      <inertia ixx="0.00014039564834146355" ixy="-5.358429276238181e-38" ixz="6.6835965943204566e-21" iyy="0.00011959285834791852" iyz="-9.863951991018341e-21" izz="7.610305038586184e-05"/>
    </inertial>
    <visual>
      <origin xyz="0.0 0.0 0.0" rpy="0.0 0.0 0.0"/>
      <geometry>
        <mesh filename="mesh/11.obj"/>
      </geometry>
      <material name="#ffffffff">
        <color rgba="1 1 1 1"/>
      </material>
    </visual>
    <collision>
      <origin xyz="0.0 0.0 0.0" rpy="0.0 0.0 0.0"/>
      <geometry>
        <mesh filename="mesh/11.obj"/>
      </geometry>
    </collision>
  </link>
  <link name="12">
    <inertial>
      <origin xyz="0.0 0.0 0.0" rpy="0.0 0.0 0.0"/>
      <mass value="0.05398256592708953"/>
      <inertia ixx="6.022603028687568e-05" ixy="-4.209434774426223e-21" ixz="1.1358641446847317e-20" iyy="2.953588936888152e-05" iyz="3.058626151082632e-06" izz="6.307968047424788e-05"/>
    </inertial>
    <visual>
      <origin xyz="0.0 0.0 0.0" rpy="0.0 0.0 0.0"/>
      <geometry>
        <mesh filename="mesh/12.obj"/>
      </geometry>
      <material name="#0000ffff">
        <color rgba="0.0 0.0 1.0 1"/>
      </material>
    </visual>
    <collision>
      <origin xyz="0.0 0.0 0.0" rpy="0.0 0.0 0.0"/>
      <geometry>
        <mesh filename="mesh/12.obj"/>
      </geometry>
    </collision>
  </link>
  <joint name="0,1" type="revolute">
    <origin xyz="0.048 0.107 0.0" rpy="1.5707963267948966 0.0 1.5707963267948966"/>
    <parent link="0"/>
    <child link="1"/>
    <axis xyz="1.0 0.0 0.0"/>
    <limit lower="-3.141592653589793" upper="3.141592653589793"/>
  </joint>
  <joint name="1,2" type="revolute">
    <origin xyz="0.066 0.0 0.0" rpy="1.5707963267948966 0.0 -1.5707963267948966"/>
    <parent link="1"/>
    <child link="2"/>
    <axis xyz="1.0 0.0 0.0"/>
    <limit lower="-1.7453292519943295" upper="1.7453292519943295"/>
  </joint>
  <joint name="2,3" type="revolute">
    <origin xyz="0.0 0.0 -0.13" rpy="0.0 0.0 -1.5707963267948966"/>
    <parent link="2"/>
    <child link="3"/>
    <axis xyz="1.0 0.0 0.0"/>
    <limit lower="-1.5707963267948966" upper="1.5707963267948966"/>
  </joint>
  <joint name="0,4" type="revolute">
    <origin xyz="0.048 -0.107 0.0" rpy="-1.5707963267948966 0.0 -1.5707963267948966"/>
    <parent link="0"/>
    <child link="4"/>
    <axis xyz="1.0 0.0 0.0"/>
    <limit lower="-3.141592653589793" upper="3.141592653589793"/>
  </joint>
  <joint name="4,5" type="revolute">
    <origin xyz="0.066 0.0 0.0" rpy="-1.5707963267948966 0.0 1.5707963267948966"/>
    <parent link="4"/>
    <child link="5"/>
    <axis xyz="1.0 0.0 0.0"/>
    <limit lower="-1.7453292519943295" upper="1.7453292519943295"/>
  </joint>
  <joint name="5,6" type="revolute">
    <origin xyz="0.0 0.0 -0.13" rpy="0.0 0.0 1.5707963267948966"/>
    <parent link="5"/>
    <child link="6"/>
    <axis xyz="1.0 0.0 0.0"/>
    <limit lower="-1.5707963267948966" upper="1.5707963267948966"/>
  </joint>
  <joint name="0,7" type="revolute">
    <origin xyz="-0.153 0.029 0.0" rpy="1.5707963267948966 0.0 1.5707963267948966"/>
    <parent link="0"/>
    <child link="7"/>
    <axis xyz="1.0 0.0 0.0"/>
    <limit lower="-3.141592653589793" upper="3.141592653589793"/>
  </joint>
  <joint name="7,8" type="revolute">
    <origin xyz="0.051000000000000004 0.0 -0.1" rpy="0.0 0.0 0.0"/>
    <parent link="7"/>
    <child link="8"/>
    <axis xyz="1.0 0.0 0.0"/>
    <limit lower="-1.7453292519943295" upper="1.7453292519943295"/>
  </joint>
  <joint name="8,9" type="revolute">
    <origin xyz="0.0 0.0 -0.112" rpy="0.0 0.0 0.0"/>
    <parent link="8"/>
    <child link="9"/>
    <axis xyz="1.0 0.0 0.0"/>
    <limit lower="-1.5707963267948966" upper="1.5707963267948966"/>
  </joint>
  <joint name="0,10" type="revolute">
    <origin xyz="-0.153 -0.029 0.0" rpy="-1.5707963267948966 0.0 -1.5707963267948966"/>
    <parent link="0"/>
    <child link="10"/>
    <axis xyz="1.0 0.0 0.0"/>
    <limit lower="-3.141592653589793" upper="3.141592653589793"/>
  </joint>
  <joint name="10,11" type="revolute">
    <origin xyz="0.051000000000000004 0.0 -0.1" rpy="0.0 0.0 0.0"/>
    <parent link="10"/>
    <child link="11"/>
    <axis xyz="1.0 0.0 0.0"/>
    <limit lower="-1.7453292519943295" upper="1.7453292519943295"/>
  </joint>
  <joint name="11,12" type="revolute">
    <origin xyz="0.0 0.0 -0.112" rpy="0.0 0.0 0.0"/>
    <parent link="11"/>
    <child link="12"/>
    <axis xyz="1.0 0.0 0.0"/>
    <limit lower="-1.5707963267948966" upper="1.5707963267948966"/>
  </joint>
</robot>
