<?xml version='1.0' encoding='UTF-8'?>
<robot name="robot">
  <link name="0">
    <inertial>
      <origin xyz="0.0 0.0 0.0" rpy="0.0 0.0 0.0"/>
      <mass value="0.6982204026089079"/>
      <inertia ixx="0.0027568162609792027" ixy="-0.0" ixz="4.3035096179499014e-05" iyy="0.00819108785451" iyz="4.969259957225228e-21" izz="0.0098023652972453"/>
    </inertial>
    <visual>
      <origin xyz="0.0 0.0 0.0" rpy="0.0 0.0 0.0"/>
      <geometry>
        <mesh filename="mesh/0.obj"/>
      </geometry>
      <material name="#ff0000ff">
        <color rgba="1.0 0.0 0.0 1"/>
      </material>
    </visual>
    <collision>
      <origin xyz="0.0 0.0 0.0" rpy="0.0 0.0 0.0"/>
      <geometry>
        <mesh filename="mesh/0.obj"/>
      </geometry>
    </collision>
  </link>
  <link name="1">
    <inertial>
      <origin xyz="0.0 0.0 0.0" rpy="0.0 0.0 0.0"/>
      <mass value="0.07174383694960039"/>
      <inertia ixx="5.842334881129862e-05" ixy="3.832305949202809e-10" ixz="-1.0679624902624474e-10" iyy="8.496352250157424e-05" iyz="-3.8649752891082553e-11" izz="6.232784253068015e-05"/>
    </inertial>
    <visual>
      <origin xyz="0.0 0.0 0.0" rpy="0.0 0.0 0.0"/>
      <geometry>
        <mesh filename="mesh/1.obj"/>
      </geometry>
      <material name="#008000ff">
        <color rgba="0.0 0.5 0.0 1"/>
      </material>
    </visual>
    <collision>
      <origin xyz="0.0 0.0 0.0" rpy="0.0 0.0 0.0"/>
      <geometry>
        <mesh filename="mesh/1.obj"/>
      </geometry>
    </collision>
  </link>
  <link name="2">
    <inertial>
      <origin xyz="0.0 0.0 0.0" rpy="0.0 0.0 0.0"/>
      <mass value="0.10679863001648698"/>
      <inertia ixx="0.0001954125803656169" ixy="4.658681209898652e-22" ixz="-5.518004738251721e-22" iyy="0.00021465960540717225" iyz="1.1166882975210138e-21" izz="8.427527620837489e-05"/>
    </inertial>
    <visual>
      <origin xyz="0.0 0.0 0.0" rpy="0.0 0.0 0.0"/>
      <geometry>
        <mesh filename="mesh/2.obj"/>
      </geometry>
      <material name="#ffffffff">
        <color rgba="1 1 1 1"/>
      </material>
    </visual>
    <collision>
      <origin xyz="0.0 0.0 0.0" rpy="0.0 0.0 0.0"/>
      <geometry>
        <mesh filename="mesh/2.obj"/>
      </geometry>
    </collision>
  </link>
  <link name="3">
    <inertial>
      <origin xyz="0.0 0.0 0.0" rpy="0.0 0.0 0.0"/>
      <mass value="0.07279808599447314"/>
      <inertia ixx="0.00010278355855422138" ixy="3.8822343415822096e-23" ixz="-9.012560357390278e-22" iyy="0.00010226588228680653" iyz="9.938519914450457e-21" izz="4.419652786409882e-05"/>
    </inertial>
    <visual>
      <origin xyz="0.0 0.0 0.0" rpy="0.0 0.0 0.0"/>
      <geometry>
        <mesh filename="mesh/3.obj"/>
      </geometry>
      <material name="#0000ffff">
        <color rgba="0.0 0.0 1.0 1"/>
      </material>
    </visual>
    <collision>
      <origin xyz="0.0 0.0 0.0" rpy="0.0 0.0 0.0"/>
      <geometry>
        <mesh filename="mesh/3.obj"/>
      </geometry>
    </collision>
  </link>
  <link name="4">
    <inertial>
      <origin xyz="0.0 0.0 0.0" rpy="0.0 0.0 0.0"/>
      <mass value="0.07174383694960039"/>
      <inertia ixx="5.842334881129862e-05" ixy="3.832305949202809e-10" ixz="-1.0679624902624474e-10" iyy="8.496352250157424e-05" iyz="-3.8649752891082553e-11" izz="6.232784253068015e-05"/>
    </inertial>
    <visual>
      <origin xyz="0.0 0.0 0.0" rpy="0.0 0.0 0.0"/>
      <geometry>
        <mesh filename="mesh/4.obj"/>
      </geometry>
      <material name="#008000ff">
        <color rgba="0.0 0.5 0.0 1"/>
      </material>
    </visual>
    <collision>
      <origin xyz="0.0 0.0 0.0" rpy="0.0 0.0 0.0"/>
      <geometry>
        <mesh filename="mesh/4.obj"/>
      </geometry>
    </collision>
  </link>
  <link name="5">
    <inertial>
      <origin xyz="0.0 0.0 0.0" rpy="0.0 0.0 0.0"/>
      <mass value="0.10679863001648698"/>
      <inertia ixx="0.0001954125803656169" ixy="4.658681209898652e-22" ixz="-5.518004738251721e-22" iyy="0.00021465960540717225" iyz="1.1166882975210138e-21" izz="8.427527620837489e-05"/>
    </inertial>
    <visual>
      <origin xyz="0.0 0.0 0.0" rpy="0.0 0.0 0.0"/>
      <geometry>
        <mesh filename="mesh/5.obj"/>
      </geometry>
      <material name="#ffffffff">
        <color rgba="1 1 1 1"/>
      </material>
    </visual>
    <collision>
      <origin xyz="0.0 0.0 0.0" rpy="0.0 0.0 0.0"/>
      <geometry>
        <mesh filename="mesh/5.obj"/>
      </geometry>
    </collision>
  </link>
  <link name="6">
    <inertial>
      <origin xyz="0.0 0.0 0.0" rpy="0.0 0.0 0.0"/>
      <mass value="0.07279808599447314"/>
      <inertia ixx="0.00010278355855422138" ixy="3.8822343415822096e-23" ixz="-9.012560357390278e-22" iyy="0.00010226588228680653" iyz="9.938519914450457e-21" izz="4.419652786409882e-05"/>
    </inertial>
    <visual>
      <origin xyz="0.0 0.0 0.0" rpy="0.0 0.0 0.0"/>
      <geometry>
        <mesh filename="mesh/6.obj"/>
      </geometry>
      <material name="#0000ffff">
        <color rgba="0.0 0.0 1.0 1"/>
      </material>
    </visual>
    <collision>
      <origin xyz="0.0 0.0 0.0" rpy="0.0 0.0 0.0"/>
      <geometry>
        <mesh filename="mesh/6.obj"/>
      </geometry>
    </collision>
  </link>
  <link name="7">
    <inertial>
      <origin xyz="0.0 0.0 0.0" rpy="0.0 0.0 0.0"/>
      <mass value="0.07174383694960039"/>
      <inertia ixx="5.842334881129862e-05" ixy="3.832305949202809e-10" ixz="-1.0679624902624474e-10" iyy="8.496352250157424e-05" iyz="-3.8649752891082553e-11" izz="6.232784253068015e-05"/>
    </inertial>
    <visual>
      <origin xyz="0.0 0.0 0.0" rpy="0.0 0.0 0.0"/>
      <geometry>
        <mesh filename="mesh/7.obj"/>
      </geometry>
      <material name="#008000ff">
        <color rgba="0.0 0.5 0.0 1"/>
      </material>
    </visual>
    <collision>
      <origin xyz="0.0 0.0 0.0" rpy="0.0 0.0 0.0"/>
      <geometry>
        <mesh filename="mesh/7.obj"/>
      </geometry>
    </collision>
  </link>
  <link name="8">
    <inertial>
      <origin xyz="0.0 0.0 0.0" rpy="0.0 0.0 0.0"/>
      <mass value="0.10679863001648698"/>
      <inertia ixx="0.0001954125803656169" ixy="4.658681209898652e-22" ixz="-5.518004738251721e-22" iyy="0.00021465960540717225" iyz="1.1166882975210138e-21" izz="8.427527620837489e-05"/>
    </inertial>
    <visual>
      <origin xyz="0.0 0.0 0.0" rpy="0.0 0.0 0.0"/>
      <geometry>
        <mesh filename="mesh/8.obj"/>
      </geometry>
      <material name="#ffffffff">
        <color rgba="1 1 1 1"/>
      </material>
    </visual>
    <collision>
      <origin xyz="0.0 0.0 0.0" rpy="0.0 0.0 0.0"/>
      <geometry>
        <mesh filename="mesh/8.obj"/>
      </geometry>
    </collision>
  </link>
  <link name="9">
    <inertial>
      <origin xyz="0.0 0.0 0.0" rpy="0.0 0.0 0.0"/>
      <mass value="0.0778070440712388"/>
      <inertia ixx="0.00011925255945703466" ixy="-6.140911165489835e-11" ixz="-1.4451720367065015e-09" iyy="0.00011092399122287756" iyz="-0.0" izz="5.476165502325008e-05"/>
    </inertial>
    <visual>
      <origin xyz="0.0 0.0 0.0" rpy="0.0 0.0 0.0"/>
      <geometry>
        <mesh filename="mesh/9.obj"/>
      </geometry>
      <material name="#0000ffff">
        <color rgba="0.0 0.0 1.0 1"/>
      </material>
    </visual>
    <collision>
      <origin xyz="0.0 0.0 0.0" rpy="0.0 0.0 0.0"/>
      <geometry>
        <mesh filename="mesh/9.obj"/>
      </geometry>
    </collision>
  </link>
  <link name="10">
    <inertial>
      <origin xyz="0.0 0.0 0.0" rpy="0.0 0.0 0.0"/>
      <mass value="0.07174383694960039"/>
      <inertia ixx="5.842334881129862e-05" ixy="3.832305949202809e-10" ixz="-1.0679624902624474e-10" iyy="8.496352250157424e-05" iyz="-3.8649752891082553e-11" izz="6.232784253068015e-05"/>
    </inertial>
    <visual>
      <origin xyz="0.0 0.0 0.0" rpy="0.0 0.0 0.0"/>
      <geometry>
        <mesh filename="mesh/10.obj"/>
      </geometry>
      <material name="#008000ff">
        <color rgba="0.0 0.5 0.0 1"/>
      </material>
    </visual>
    <collision>
      <origin xyz="0.0 0.0 0.0" rpy="0.0 0.0 0.0"/>
      <geometry>
        <mesh filename="mesh/10.obj"/>
      </geometry>
    </collision>
  </link>
  <link name="11">
    <inertial>
      <origin xyz="0.0 0.0 0.0" rpy="0.0 0.0 0.0"/>
      <mass value="0.10679863001648698"/>
      <inertia ixx="0.0001954125803656169" ixy="4.658681209898652e-22" ixz="-5.518004738251721e-22" iyy="0.00021465960540717225" iyz="1.1166882975210138e-21" izz="8.427527620837489e-05"/>
    </inertial>
    <visual>
      <origin xyz="0.0 0.0 0.0" rpy="0.0 0.0 0.0"/>
      <geometry>
        <mesh filename="mesh/11.obj"/>
      </geometry>
      <material name="#ffffffff">
        <color rgba="1 1 1 1"/>
      </material>
    </visual>
    <collision>
      <origin xyz="0.0 0.0 0.0" rpy="0.0 0.0 0.0"/>
      <geometry>
        <mesh filename="mesh/11.obj"/>
      </geometry>
    </collision>
  </link>
  <link name="12">
    <inertial>
      <origin xyz="0.0 0.0 0.0" rpy="0.0 0.0 0.0"/>
      <mass value="0.0778070440712388"/>
      <inertia ixx="0.00011925255945703451" ixy="-6.140911165524776e-11" ixz="1.4451720366959905e-09" iyy="0.00011092399122287741" iyz="-1.2280156809005117e-20" izz="5.476165502325008e-05"/>
    </inertial>
    <visual>
      <origin xyz="0.0 0.0 0.0" rpy="0.0 0.0 0.0"/>
      <geometry>
        <mesh filename="mesh/12.obj"/>
      </geometry>
      <material name="#0000ffff">
        <color rgba="0.0 0.0 1.0 1"/>
      </material>
    </visual>
    <collision>
      <origin xyz="0.0 0.0 0.0" rpy="0.0 0.0 0.0"/>
      <geometry>
        <mesh filename="mesh/12.obj"/>
      </geometry>
    </collision>
  </link>
  <joint name="0,1" type="revolute">
    <origin xyz="0.07 0.107 0.0" rpy="1.5707963267948966 0.0 1.5707963267948966"/>
    <parent link="0"/>
    <child link="1"/>
    <axis xyz="1.0 0.0 0.0"/>
    <limit lower="-3.141592653589793" upper="3.141592653589793"/>
  </joint>
  <joint name="1,2" type="revolute">
    <origin xyz="0.066 0.0 0.0" rpy="1.5707963267948966 0.0 -1.5707963267948966"/>
    <parent link="1"/>
    <child link="2"/>
    <axis xyz="1.0 0.0 0.0"/>
    <limit lower="-1.7453292519943295" upper="1.7453292519943295"/>
  </joint>
  <joint name="2,3" type="revolute">
    <origin xyz="0.0 0.0 -0.14300000000000002" rpy="0.0 0.0 -1.5707963267948963"/>
    <parent link="2"/>
    <child link="3"/>
    <axis xyz="1.0 0.0 0.0"/>
    <limit lower="-1.5707963267948966" upper="1.5707963267948966"/>
  </joint>
  <joint name="0,4" type="revolute">
    <origin xyz="0.07 -0.107 0.0" rpy="-1.5707963267948966 0.0 -1.5707963267948966"/>
    <parent link="0"/>
    <child link="4"/>
    <axis xyz="1.0 0.0 0.0"/>
    <limit lower="-3.141592653589793" upper="3.141592653589793"/>
  </joint>
  <joint name="4,5" type="revolute">
    <origin xyz="0.066 0.0 0.0" rpy="-1.5707963267948966 0.0 1.5707963267948966"/>
    <parent link="4"/>
    <child link="5"/>
    <axis xyz="1.0 0.0 0.0"/>
    <limit lower="-1.7453292519943295" upper="1.7453292519943295"/>
  </joint>
  <joint name="5,6" type="revolute">
    <origin xyz="0.0 0.0 -0.14300000000000002" rpy="0.0 0.0 1.5707963267948963"/>
    <parent link="5"/>
    <child link="6"/>
    <axis xyz="1.0 0.0 0.0"/>
    <limit lower="-1.5707963267948966" upper="1.5707963267948966"/>
  </joint>
  <joint name="0,7" type="revolute">
    <origin xyz="-0.17500000000000002 0.03 0.0" rpy="1.5707963267948966 0.0 1.5707963267948966"/>
    <parent link="0"/>
    <child link="7"/>
    <axis xyz="1.0 0.0 0.0"/>
    <limit lower="-3.141592653589793" upper="3.141592653589793"/>
  </joint>
  <joint name="7,8" type="revolute">
    <origin xyz="0.066 0.0 0.0" rpy="1.5707963267948966 0.0 -1.5707963267948966"/>
    <parent link="7"/>
    <child link="8"/>
    <axis xyz="1.0 0.0 0.0"/>
    <limit lower="-1.7453292519943295" upper="1.7453292519943295"/>
  </joint>
  <joint name="8,9" type="revolute">
    <origin xyz="0.0 0.0 -0.14300000000000002" rpy="0.0 0.0 -1.5707963267948963"/>
    <parent link="8"/>
    <child link="9"/>
    <axis xyz="1.0 0.0 0.0"/>
    <limit lower="-1.5707963267948966" upper="1.5707963267948966"/>
  </joint>
  <joint name="0,10" type="revolute">
    <origin xyz="-0.17500000000000002 -0.03 0.0" rpy="-1.5707963267948966 0.0 -1.5707963267948966"/>
    <parent link="0"/>
    <child link="10"/>
    <axis xyz="1.0 0.0 0.0"/>
    <limit lower="-3.141592653589793" upper="3.141592653589793"/>
  </joint>
  <joint name="10,11" type="revolute">
    <origin xyz="0.066 0.0 0.0" rpy="-1.5707963267948966 0.0 1.5707963267948966"/>
    <parent link="10"/>
    <child link="11"/>
    <axis xyz="1.0 0.0 0.0"/>
    <limit lower="-1.7453292519943295" upper="1.7453292519943295"/>
  </joint>
  <joint name="11,12" type="revolute">
    <origin xyz="0.0 0.0 -0.14300000000000002" rpy="0.0 0.0 1.5707963267948963"/>
    <parent link="11"/>
    <child link="12"/>
    <axis xyz="1.0 0.0 0.0"/>
    <limit lower="-1.5707963267948966" upper="1.5707963267948966"/>
  </joint>
</robot>
