<?xml version='1.0' encoding='UTF-8'?>
<robot name="robot">
  <link name="0">
    <inertial>
      <origin xyz="0.0 0.0 0.0" rpy="0.0 0.0 0.0"/>
      <mass value="0.6139850203204843"/>
      <inertia ixx="0.0023968969228688243" ixy="-3.909284391631402e-20" ixz="3.9479226721196734e-05" iyy="0.00500797781203553" iyz="-1.0768525620648075e-21" izz="0.0064139690096911275"/>
    </inertial>
    <visual>
      <origin xyz="0.0 0.0 0.0" rpy="0.0 0.0 0.0"/>
      <geometry>
        <mesh filename="mesh/0.obj"/>
      </geometry>
      <material name="#ff0000ff">
        <color rgba="1.0 0.0 0.0 1"/>
      </material>
    </visual>
    <collision>
      <origin xyz="0.0 0.0 0.0" rpy="0.0 0.0 0.0"/>
      <geometry>
        <mesh filename="mesh/0.obj"/>
      </geometry>
    </collision>
  </link>
  <link name="1">
    <inertial>
      <origin xyz="0.0 0.0 0.0" rpy="0.0 0.0 0.0"/>
      <mass value="0.07269017067211427"/>
      <inertia ixx="5.890215759579382e-05" ixy="3.019754432705555e-10" ixz="5.436432049982791e-11" iyy="8.024576882477195e-05" iyz="-6.214062745464443e-11" izz="6.418317475691778e-05"/>
    </inertial>
    <visual>
      <origin xyz="0.0 0.0 0.0" rpy="0.0 0.0 0.0"/>
      <geometry>
        <mesh filename="mesh/1.obj"/>
      </geometry>
      <material name="#008000ff">
        <color rgba="0.0 0.5 0.0 1"/>
      </material>
    </visual>
    <collision>
      <origin xyz="0.0 0.0 0.0" rpy="0.0 0.0 0.0"/>
      <geometry>
        <mesh filename="mesh/1.obj"/>
      </geometry>
    </collision>
  </link>
  <link name="2">
    <inertial>
      <origin xyz="0.0 0.0 0.0" rpy="0.0 0.0 0.0"/>
      <mass value="0.09857950140569696"/>
      <inertia ixx="0.00015801174289584922" ixy="3.105787473265769e-22" ixz="5.310444628340301e-22" iyy="0.00017389559096697184" iyz="1.2148912375055951e-20" izz="7.613674281767581e-05"/>
    </inertial>
    <visual>
      <origin xyz="0.0 0.0 0.0" rpy="0.0 0.0 0.0"/>
      <geometry>
        <mesh filename="mesh/2.obj"/>
      </geometry>
      <material name="#ffffffff">
        <color rgba="1 1 1 1"/>
      </material>
    </visual>
    <collision>
      <origin xyz="0.0 0.0 0.0" rpy="0.0 0.0 0.0"/>
      <geometry>
        <mesh filename="mesh/2.obj"/>
      </geometry>
    </collision>
  </link>
  <link name="3">
    <inertial>
      <origin xyz="0.0 0.0 0.0" rpy="0.0 0.0 0.0"/>
      <mass value="0.05961127877722497"/>
      <inertia ixx="6.143768285533723e-05" ixy="2.6245108516620497e-10" ixz="-9.28399731434094e-11" iyy="6.001893411295294e-05" iyz="-5.141603680911952e-10" izz="3.627869762810086e-05"/>
    </inertial>
    <visual>
      <origin xyz="0.0 0.0 0.0" rpy="0.0 0.0 0.0"/>
      <geometry>
        <mesh filename="mesh/3.obj"/>
      </geometry>
      <material name="#0000ffff">
        <color rgba="0.0 0.0 1.0 1"/>
      </material>
    </visual>
    <collision>
      <origin xyz="0.0 0.0 0.0" rpy="0.0 0.0 0.0"/>
      <geometry>
        <mesh filename="mesh/3.obj"/>
      </geometry>
    </collision>
  </link>
  <link name="4">
    <inertial>
      <origin xyz="0.0 0.0 0.0" rpy="0.0 0.0 0.0"/>
      <mass value="0.07269017067211427"/>
      <inertia ixx="5.890215759579382e-05" ixy="3.019754432705555e-10" ixz="5.436432049982791e-11" iyy="8.024576882477195e-05" iyz="-6.214062745464443e-11" izz="6.418317475691778e-05"/>
    </inertial>
    <visual>
      <origin xyz="0.0 0.0 0.0" rpy="0.0 0.0 0.0"/>
      <geometry>
        <mesh filename="mesh/4.obj"/>
      </geometry>
      <material name="#008000ff">
        <color rgba="0.0 0.5 0.0 1"/>
      </material>
    </visual>
    <collision>
      <origin xyz="0.0 0.0 0.0" rpy="0.0 0.0 0.0"/>
      <geometry>
        <mesh filename="mesh/4.obj"/>
      </geometry>
    </collision>
  </link>
  <link name="5">
    <inertial>
      <origin xyz="0.0 0.0 0.0" rpy="0.0 0.0 0.0"/>
      <mass value="0.09857950140569696"/>
      <inertia ixx="0.00015801174289584922" ixy="3.105787473265769e-22" ixz="5.310444628340301e-22" iyy="0.00017389559096697184" iyz="1.2148912375055951e-20" izz="7.613674281767581e-05"/>
    </inertial>
    <visual>
      <origin xyz="0.0 0.0 0.0" rpy="0.0 0.0 0.0"/>
      <geometry>
        <mesh filename="mesh/5.obj"/>
      </geometry>
      <material name="#ffffffff">
        <color rgba="1 1 1 1"/>
      </material>
    </visual>
    <collision>
      <origin xyz="0.0 0.0 0.0" rpy="0.0 0.0 0.0"/>
      <geometry>
        <mesh filename="mesh/5.obj"/>
      </geometry>
    </collision>
  </link>
  <link name="6">
    <inertial>
      <origin xyz="0.0 0.0 0.0" rpy="0.0 0.0 0.0"/>
      <mass value="0.05961127877722497"/>
      <inertia ixx="6.143768285533723e-05" ixy="2.6245108516620497e-10" ixz="-9.28399731434094e-11" iyy="6.001893411295294e-05" iyz="-5.141603680911952e-10" izz="3.627869762810086e-05"/>
    </inertial>
    <visual>
      <origin xyz="0.0 0.0 0.0" rpy="0.0 0.0 0.0"/>
      <geometry>
        <mesh filename="mesh/6.obj"/>
      </geometry>
      <material name="#0000ffff">
        <color rgba="0.0 0.0 1.0 1"/>
      </material>
    </visual>
    <collision>
      <origin xyz="0.0 0.0 0.0" rpy="0.0 0.0 0.0"/>
      <geometry>
        <mesh filename="mesh/6.obj"/>
      </geometry>
    </collision>
  </link>
  <link name="7">
    <inertial>
      <origin xyz="0.0 0.0 0.0" rpy="0.0 0.0 0.0"/>
      <mass value="0.07269017067211427"/>
      <inertia ixx="5.890215759579382e-05" ixy="3.019754432705555e-10" ixz="5.436432049982791e-11" iyy="8.024576882477195e-05" iyz="-6.214062745464443e-11" izz="6.418317475691778e-05"/>
    </inertial>
    <visual>
      <origin xyz="0.0 0.0 0.0" rpy="0.0 0.0 0.0"/>
      <geometry>
        <mesh filename="mesh/7.obj"/>
      </geometry>
      <material name="#008000ff">
        <color rgba="0.0 0.5 0.0 1"/>
      </material>
    </visual>
    <collision>
      <origin xyz="0.0 0.0 0.0" rpy="0.0 0.0 0.0"/>
      <geometry>
        <mesh filename="mesh/7.obj"/>
      </geometry>
    </collision>
  </link>
  <link name="8">
    <inertial>
      <origin xyz="0.0 0.0 0.0" rpy="0.0 0.0 0.0"/>
      <mass value="0.09857950140569696"/>
      <inertia ixx="0.00015801174289584922" ixy="3.105787473265769e-22" ixz="5.310444628340301e-22" iyy="0.00017389559096697184" iyz="1.2148912375055951e-20" izz="7.613674281767581e-05"/>
    </inertial>
    <visual>
      <origin xyz="0.0 0.0 0.0" rpy="0.0 0.0 0.0"/>
      <geometry>
        <mesh filename="mesh/8.obj"/>
      </geometry>
      <material name="#ffffffff">
        <color rgba="1 1 1 1"/>
      </material>
    </visual>
    <collision>
      <origin xyz="0.0 0.0 0.0" rpy="0.0 0.0 0.0"/>
      <geometry>
        <mesh filename="mesh/8.obj"/>
      </geometry>
    </collision>
  </link>
  <link name="9">
    <inertial>
      <origin xyz="0.0 0.0 0.0" rpy="0.0 0.0 0.0"/>
      <mass value="0.06025949243310835"/>
      <inertia ixx="7.76526724867455e-05" ixy="-2.3587075316669736e-10" ixz="-1.1160737265181388e-09" iyy="4.095167354316038e-05" iyz="2.3801515920840335e-06" izz="7.283755239770136e-05"/>
    </inertial>
    <visual>
      <origin xyz="0.0 0.0 0.0" rpy="0.0 0.0 0.0"/>
      <geometry>
        <mesh filename="mesh/9.obj"/>
      </geometry>
      <material name="#0000ffff">
        <color rgba="0.0 0.0 1.0 1"/>
      </material>
    </visual>
    <collision>
      <origin xyz="0.0 0.0 0.0" rpy="0.0 0.0 0.0"/>
      <geometry>
        <mesh filename="mesh/9.obj"/>
      </geometry>
    </collision>
  </link>
  <link name="10">
    <inertial>
      <origin xyz="0.0 0.0 0.0" rpy="0.0 0.0 0.0"/>
      <mass value="0.07269017067211427"/>
      <inertia ixx="5.890215759579382e-05" ixy="3.019754432705555e-10" ixz="5.436432049982791e-11" iyy="8.024576882477195e-05" iyz="-6.214062745464443e-11" izz="6.418317475691778e-05"/>
    </inertial>
    <visual>
      <origin xyz="0.0 0.0 0.0" rpy="0.0 0.0 0.0"/>
      <geometry>
        <mesh filename="mesh/10.obj"/>
      </geometry>
      <material name="#008000ff">
        <color rgba="0.0 0.5 0.0 1"/>
      </material>
    </visual>
    <collision>
      <origin xyz="0.0 0.0 0.0" rpy="0.0 0.0 0.0"/>
      <geometry>
        <mesh filename="mesh/10.obj"/>
      </geometry>
    </collision>
  </link>
  <link name="11">
    <inertial>
      <origin xyz="0.0 0.0 0.0" rpy="0.0 0.0 0.0"/>
      <mass value="0.09857950140569696"/>
      <inertia ixx="0.00015801174289584922" ixy="3.105787473265769e-22" ixz="5.310444628340301e-22" iyy="0.00017389559096697184" iyz="1.2148912375055951e-20" izz="7.613674281767581e-05"/>
    </inertial>
    <visual>
      <origin xyz="0.0 0.0 0.0" rpy="0.0 0.0 0.0"/>
      <geometry>
        <mesh filename="mesh/11.obj"/>
      </geometry>
      <material name="#ffffffff">
        <color rgba="1 1 1 1"/>
      </material>
    </visual>
    <collision>
      <origin xyz="0.0 0.0 0.0" rpy="0.0 0.0 0.0"/>
      <geometry>
        <mesh filename="mesh/11.obj"/>
      </geometry>
    </collision>
  </link>
  <link name="12">
    <inertial>
      <origin xyz="0.0 0.0 0.0" rpy="0.0 0.0 0.0"/>
      <mass value="0.06025949243310835"/>
      <inertia ixx="7.76526724867455e-05" ixy="-2.3587075317306433e-10" ixz="1.1160737265082003e-09" iyy="4.095167354316038e-05" iyz="-2.380151592084015e-06" izz="7.283755239770136e-05"/>
    </inertial>
    <visual>
      <origin xyz="0.0 0.0 0.0" rpy="0.0 0.0 0.0"/>
      <geometry>
        <mesh filename="mesh/12.obj"/>
      </geometry>
      <material name="#0000ffff">
        <color rgba="0.0 0.0 1.0 1"/>
      </material>
    </visual>
    <collision>
      <origin xyz="0.0 0.0 0.0" rpy="0.0 0.0 0.0"/>
      <geometry>
        <mesh filename="mesh/12.obj"/>
      </geometry>
    </collision>
  </link>
  <joint name="0,1" type="revolute">
    <origin xyz="0.048 0.107 0.0" rpy="1.5707963267948966 0.0 1.5707963267948966"/>
    <parent link="0"/>
    <child link="1"/>
    <axis xyz="1.0 0.0 0.0"/>
    <limit lower="-3.141592653589793" upper="3.141592653589793"/>
  </joint>
  <joint name="1,2" type="revolute">
    <origin xyz="0.066 0.0 0.0" rpy="1.5707963267948966 0.0 -1.5707963267948966"/>
    <parent link="1"/>
    <child link="2"/>
    <axis xyz="1.0 0.0 0.0"/>
    <limit lower="-1.7453292519943295" upper="1.7453292519943295"/>
  </joint>
  <joint name="2,3" type="revolute">
    <origin xyz="0.0 0.0 -0.13" rpy="0.0 0.0 -1.5707963267948963"/>
    <parent link="2"/>
    <child link="3"/>
    <axis xyz="1.0 0.0 0.0"/>
    <limit lower="-1.5707963267948966" upper="1.5707963267948966"/>
  </joint>
  <joint name="0,4" type="revolute">
    <origin xyz="0.048 -0.107 0.0" rpy="-1.5707963267948966 0.0 -1.5707963267948966"/>
    <parent link="0"/>
    <child link="4"/>
    <axis xyz="1.0 0.0 0.0"/>
    <limit lower="-3.141592653589793" upper="3.141592653589793"/>
  </joint>
  <joint name="4,5" type="revolute">
    <origin xyz="0.066 0.0 0.0" rpy="-1.5707963267948966 0.0 1.5707963267948966"/>
    <parent link="4"/>
    <child link="5"/>
    <axis xyz="1.0 0.0 0.0"/>
    <limit lower="-1.7453292519943295" upper="1.7453292519943295"/>
  </joint>
  <joint name="5,6" type="revolute">
    <origin xyz="0.0 0.0 -0.13" rpy="0.0 0.0 1.5707963267948963"/>
    <parent link="5"/>
    <child link="6"/>
    <axis xyz="1.0 0.0 0.0"/>
    <limit lower="-1.5707963267948966" upper="1.5707963267948966"/>
  </joint>
  <joint name="0,7" type="revolute">
    <origin xyz="-0.153 0.03 0.0" rpy="1.5707963267948966 0.0 1.5707963267948966"/>
    <parent link="0"/>
    <child link="7"/>
    <axis xyz="1.0 0.0 0.0"/>
    <limit lower="-3.141592653589793" upper="3.141592653589793"/>
  </joint>
  <joint name="7,8" type="revolute">
    <origin xyz="0.066 0.0 0.0" rpy="1.5707963267948966 0.0 -1.5707963267948966"/>
    <parent link="7"/>
    <child link="8"/>
    <axis xyz="1.0 0.0 0.0"/>
    <limit lower="-1.7453292519943295" upper="1.7453292519943295"/>
  </joint>
  <joint name="8,9" type="revolute">
    <origin xyz="0.0 0.0 -0.13" rpy="0.0 0.0 -1.5707963267948963"/>
    <parent link="8"/>
    <child link="9"/>
    <axis xyz="1.0 0.0 0.0"/>
    <limit lower="-1.5707963267948966" upper="1.5707963267948966"/>
  </joint>
  <joint name="0,10" type="revolute">
    <origin xyz="-0.153 -0.03 0.0" rpy="-1.5707963267948966 0.0 -1.5707963267948966"/>
    <parent link="0"/>
    <child link="10"/>
    <axis xyz="1.0 0.0 0.0"/>
    <limit lower="-3.141592653589793" upper="3.141592653589793"/>
  </joint>
  <joint name="10,11" type="revolute">
    <origin xyz="0.066 0.0 0.0" rpy="-1.5707963267948966 0.0 1.5707963267948966"/>
    <parent link="10"/>
    <child link="11"/>
    <axis xyz="1.0 0.0 0.0"/>
    <limit lower="-1.7453292519943295" upper="1.7453292519943295"/>
  </joint>
  <joint name="11,12" type="revolute">
    <origin xyz="0.0 0.0 -0.13" rpy="0.0 0.0 1.5707963267948963"/>
    <parent link="11"/>
    <child link="12"/>
    <axis xyz="1.0 0.0 0.0"/>
    <limit lower="-1.5707963267948966" upper="1.5707963267948966"/>
  </joint>
</robot>
